2015-11-02 16:51:14,920 INFO: microblog startup [in /home/microblog/app/__init__.py:36]
2015-11-02 16:51:26,927 ERROR: Exception on /edit [POST] [in /home/microblog/flask/local/lib/python2.7/site-packages/flask/app.py:1423]
Traceback (most recent call last):
  File "/home/microblog/flask/local/lib/python2.7/site-packages/flask/app.py", line 1817, in wsgi_app
    response = self.full_dispatch_request()
  File "/home/microblog/flask/local/lib/python2.7/site-packages/flask/app.py", line 1477, in full_dispatch_request
    rv = self.handle_user_exception(e)
  File "/home/microblog/flask/local/lib/python2.7/site-packages/flask/app.py", line 1381, in handle_user_exception
    reraise(exc_type, exc_value, tb)
  File "/home/microblog/flask/local/lib/python2.7/site-packages/flask/app.py", line 1475, in full_dispatch_request
    rv = self.dispatch_request()
  File "/home/microblog/flask/local/lib/python2.7/site-packages/flask/app.py", line 1461, in dispatch_request
    return self.view_functions[rule.endpoint](**req.view_args)
  File "/home/microblog/flask/local/lib/python2.7/site-packages/flask_login.py", line 792, in decorated_view
    return func(*args, **kwargs)
  File "/home/microblog/app/views.py", line 104, in edit
    db.session.commit()
  File "/home/microblog/flask/local/lib/python2.7/site-packages/sqlalchemy/orm/scoping.py", line 150, in do
    return getattr(self.registry(), name)(*args, **kwargs)
  File "/home/microblog/flask/local/lib/python2.7/site-packages/sqlalchemy/orm/session.py", line 801, in commit
    self.transaction.commit()
  File "/home/microblog/flask/local/lib/python2.7/site-packages/sqlalchemy/orm/session.py", line 392, in commit
    self._prepare_impl()
  File "/home/microblog/flask/local/lib/python2.7/site-packages/sqlalchemy/orm/session.py", line 372, in _prepare_impl
    self.session.flush()
  File "/home/microblog/flask/local/lib/python2.7/site-packages/sqlalchemy/orm/session.py", line 2015, in flush
    self._flush(objects)
  File "/home/microblog/flask/local/lib/python2.7/site-packages/sqlalchemy/orm/session.py", line 2133, in _flush
    transaction.rollback(_capture_exception=True)
  File "/home/microblog/flask/local/lib/python2.7/site-packages/sqlalchemy/util/langhelpers.py", line 60, in __exit__
    compat.reraise(exc_type, exc_value, exc_tb)
  File "/home/microblog/flask/local/lib/python2.7/site-packages/sqlalchemy/orm/session.py", line 2097, in _flush
    flush_context.execute()
  File "/home/microblog/flask/local/lib/python2.7/site-packages/sqlalchemy/orm/unitofwork.py", line 373, in execute
    rec.execute(self)
  File "/home/microblog/flask/local/lib/python2.7/site-packages/sqlalchemy/orm/unitofwork.py", line 532, in execute
    uow
  File "/home/microblog/flask/local/lib/python2.7/site-packages/sqlalchemy/orm/persistence.py", line 170, in save_obj
    mapper, table, update)
  File "/home/microblog/flask/local/lib/python2.7/site-packages/sqlalchemy/orm/persistence.py", line 694, in _emit_update_statements
    execute(statement, multiparams)
  File "/home/microblog/flask/local/lib/python2.7/site-packages/sqlalchemy/engine/base.py", line 914, in execute
    return meth(self, multiparams, params)
  File "/home/microblog/flask/local/lib/python2.7/site-packages/sqlalchemy/sql/elements.py", line 323, in _execute_on_connection
    return connection._execute_clauseelement(self, multiparams, params)
  File "/home/microblog/flask/local/lib/python2.7/site-packages/sqlalchemy/engine/base.py", line 1010, in _execute_clauseelement
    compiled_sql, distilled_params
  File "/home/microblog/flask/local/lib/python2.7/site-packages/sqlalchemy/engine/base.py", line 1146, in _execute_context
    context)
  File "/home/microblog/flask/local/lib/python2.7/site-packages/sqlalchemy/engine/base.py", line 1341, in _handle_dbapi_exception
    exc_info
  File "/home/microblog/flask/local/lib/python2.7/site-packages/sqlalchemy/util/compat.py", line 199, in raise_from_cause
    reraise(type(exception), exception, tb=exc_tb)
  File "/home/microblog/flask/local/lib/python2.7/site-packages/sqlalchemy/engine/base.py", line 1139, in _execute_context
    context)
  File "/home/microblog/flask/local/lib/python2.7/site-packages/sqlalchemy/engine/default.py", line 450, in do_execute
    cursor.execute(statement, parameters)
IntegrityError: (sqlite3.IntegrityError) column nickname is not unique [SQL: u'UPDATE user SET nickname=?, about_me=? WHERE user.id = ?'] [parameters: (u'dup', u'', 2)]
2015-11-02 16:51:43,866 ERROR: Exception on /edit [POST] [in /home/microblog/flask/local/lib/python2.7/site-packages/flask/app.py:1423]
Traceback (most recent call last):
  File "/home/microblog/flask/local/lib/python2.7/site-packages/flask/app.py", line 1817, in wsgi_app
    response = self.full_dispatch_request()
  File "/home/microblog/flask/local/lib/python2.7/site-packages/flask/app.py", line 1477, in full_dispatch_request
    rv = self.handle_user_exception(e)
  File "/home/microblog/flask/local/lib/python2.7/site-packages/flask/app.py", line 1381, in handle_user_exception
    reraise(exc_type, exc_value, tb)
  File "/home/microblog/flask/local/lib/python2.7/site-packages/flask/app.py", line 1475, in full_dispatch_request
    rv = self.dispatch_request()
  File "/home/microblog/flask/local/lib/python2.7/site-packages/flask/app.py", line 1461, in dispatch_request
    return self.view_functions[rule.endpoint](**req.view_args)
  File "/home/microblog/flask/local/lib/python2.7/site-packages/flask_login.py", line 792, in decorated_view
    return func(*args, **kwargs)
  File "/home/microblog/app/views.py", line 104, in edit
    db.session.commit()
  File "/home/microblog/flask/local/lib/python2.7/site-packages/sqlalchemy/orm/scoping.py", line 150, in do
    return getattr(self.registry(), name)(*args, **kwargs)
  File "/home/microblog/flask/local/lib/python2.7/site-packages/sqlalchemy/orm/session.py", line 801, in commit
    self.transaction.commit()
  File "/home/microblog/flask/local/lib/python2.7/site-packages/sqlalchemy/orm/session.py", line 392, in commit
    self._prepare_impl()
  File "/home/microblog/flask/local/lib/python2.7/site-packages/sqlalchemy/orm/session.py", line 372, in _prepare_impl
    self.session.flush()
  File "/home/microblog/flask/local/lib/python2.7/site-packages/sqlalchemy/orm/session.py", line 2015, in flush
    self._flush(objects)
  File "/home/microblog/flask/local/lib/python2.7/site-packages/sqlalchemy/orm/session.py", line 2133, in _flush
    transaction.rollback(_capture_exception=True)
  File "/home/microblog/flask/local/lib/python2.7/site-packages/sqlalchemy/util/langhelpers.py", line 60, in __exit__
    compat.reraise(exc_type, exc_value, exc_tb)
  File "/home/microblog/flask/local/lib/python2.7/site-packages/sqlalchemy/orm/session.py", line 2097, in _flush
    flush_context.execute()
  File "/home/microblog/flask/local/lib/python2.7/site-packages/sqlalchemy/orm/unitofwork.py", line 373, in execute
    rec.execute(self)
  File "/home/microblog/flask/local/lib/python2.7/site-packages/sqlalchemy/orm/unitofwork.py", line 532, in execute
    uow
  File "/home/microblog/flask/local/lib/python2.7/site-packages/sqlalchemy/orm/persistence.py", line 170, in save_obj
    mapper, table, update)
  File "/home/microblog/flask/local/lib/python2.7/site-packages/sqlalchemy/orm/persistence.py", line 694, in _emit_update_statements
    execute(statement, multiparams)
  File "/home/microblog/flask/local/lib/python2.7/site-packages/sqlalchemy/engine/base.py", line 914, in execute
    return meth(self, multiparams, params)
  File "/home/microblog/flask/local/lib/python2.7/site-packages/sqlalchemy/sql/elements.py", line 323, in _execute_on_connection
    return connection._execute_clauseelement(self, multiparams, params)
  File "/home/microblog/flask/local/lib/python2.7/site-packages/sqlalchemy/engine/base.py", line 1010, in _execute_clauseelement
    compiled_sql, distilled_params
  File "/home/microblog/flask/local/lib/python2.7/site-packages/sqlalchemy/engine/base.py", line 1146, in _execute_context
    context)
  File "/home/microblog/flask/local/lib/python2.7/site-packages/sqlalchemy/engine/base.py", line 1341, in _handle_dbapi_exception
    exc_info
  File "/home/microblog/flask/local/lib/python2.7/site-packages/sqlalchemy/util/compat.py", line 199, in raise_from_cause
    reraise(type(exception), exception, tb=exc_tb)
  File "/home/microblog/flask/local/lib/python2.7/site-packages/sqlalchemy/engine/base.py", line 1139, in _execute_context
    context)
  File "/home/microblog/flask/local/lib/python2.7/site-packages/sqlalchemy/engine/default.py", line 450, in do_execute
    cursor.execute(statement, parameters)
IntegrityError: (sqlite3.IntegrityError) column nickname is not unique [SQL: u'UPDATE user SET nickname=?, about_me=? WHERE user.id = ?'] [parameters: (u'dup', u'', 2)]
2015-11-03 15:34:38,538 INFO: microblog startup [in /home/microblog/app/__init__.py:36]
2015-11-03 15:35:04,274 INFO: microblog startup [in /home/microblog/app/__init__.py:36]
2015-11-03 15:42:40,498 INFO: microblog startup [in /home/microblog/app/__init__.py:36]
2015-11-04 10:04:05,924 INFO: microblog startup [in /home/microblog/app/__init__.py:36]
2015-11-04 10:09:48,132 INFO: microblog startup [in /home/microblog/app/__init__.py:36]
2015-11-04 10:09:56,716 INFO: microblog startup [in /home/microblog/app/__init__.py:36]
2015-11-04 10:15:27,125 INFO: microblog startup [in /home/microblog/app/__init__.py:36]
2015-11-04 10:33:36,057 INFO: microblog startup [in /home/microblog/app/__init__.py:36]
2015-11-04 11:41:25,952 INFO: microblog startup [in /home/microblog/app/__init__.py:36]
2015-11-04 11:43:48,353 INFO: microblog startup [in /home/microblog/app/__init__.py:36]
2015-11-04 11:51:24,728 INFO: microblog startup [in /home/microblog/app/__init__.py:36]
2015-11-04 11:51:32,112 INFO: microblog startup [in /home/microblog/app/__init__.py:36]
2015-11-04 13:46:25,797 INFO: microblog startup [in /home/microblog/app/__init__.py:36]
2015-11-04 14:14:26,943 INFO: microblog startup [in /home/microblog/app/__init__.py:36]
2015-11-04 14:14:47,263 INFO: microblog startup [in /home/microblog/app/__init__.py:36]
2015-11-04 14:32:26,549 INFO: microblog startup [in /home/microblog/app/__init__.py:36]
2015-11-04 14:33:53,389 INFO: microblog startup [in /home/microblog/app/__init__.py:36]
2015-11-04 14:34:05,360 ERROR: Exception on /index [GET] [in /home/microblog/flask/local/lib/python2.7/site-packages/flask/app.py:1423]
Traceback (most recent call last):
  File "/home/microblog/flask/local/lib/python2.7/site-packages/flask/app.py", line 1817, in wsgi_app
    response = self.full_dispatch_request()
  File "/home/microblog/flask/local/lib/python2.7/site-packages/flask/app.py", line 1477, in full_dispatch_request
    rv = self.handle_user_exception(e)
  File "/home/microblog/flask/local/lib/python2.7/site-packages/flask/app.py", line 1381, in handle_user_exception
    reraise(exc_type, exc_value, tb)
  File "/home/microblog/flask/local/lib/python2.7/site-packages/flask/app.py", line 1475, in full_dispatch_request
    rv = self.dispatch_request()
  File "/home/microblog/flask/local/lib/python2.7/site-packages/flask/app.py", line 1461, in dispatch_request
    return self.view_functions[rule.endpoint](**req.view_args)
  File "/home/microblog/flask/local/lib/python2.7/site-packages/flask_login.py", line 792, in decorated_view
    return func(*args, **kwargs)
  File "/home/microblog/app/views.py", line 73, in index
    posts = g.user.followed_posts().paginate(page, POSTS_PER_PAGE, False).items
NameError: global name 'page' is not defined
2015-11-04 14:34:08,757 ERROR: Exception on /index [GET] [in /home/microblog/flask/local/lib/python2.7/site-packages/flask/app.py:1423]
Traceback (most recent call last):
  File "/home/microblog/flask/local/lib/python2.7/site-packages/flask/app.py", line 1817, in wsgi_app
    response = self.full_dispatch_request()
  File "/home/microblog/flask/local/lib/python2.7/site-packages/flask/app.py", line 1477, in full_dispatch_request
    rv = self.handle_user_exception(e)
  File "/home/microblog/flask/local/lib/python2.7/site-packages/flask/app.py", line 1381, in handle_user_exception
    reraise(exc_type, exc_value, tb)
  File "/home/microblog/flask/local/lib/python2.7/site-packages/flask/app.py", line 1475, in full_dispatch_request
    rv = self.dispatch_request()
  File "/home/microblog/flask/local/lib/python2.7/site-packages/flask/app.py", line 1461, in dispatch_request
    return self.view_functions[rule.endpoint](**req.view_args)
  File "/home/microblog/flask/local/lib/python2.7/site-packages/flask_login.py", line 792, in decorated_view
    return func(*args, **kwargs)
  File "/home/microblog/app/views.py", line 73, in index
    posts = g.user.followed_posts().paginate(page, POSTS_PER_PAGE, False).items
NameError: global name 'page' is not defined
2015-11-04 14:34:10,516 ERROR: Exception on /index [GET] [in /home/microblog/flask/local/lib/python2.7/site-packages/flask/app.py:1423]
Traceback (most recent call last):
  File "/home/microblog/flask/local/lib/python2.7/site-packages/flask/app.py", line 1817, in wsgi_app
    response = self.full_dispatch_request()
  File "/home/microblog/flask/local/lib/python2.7/site-packages/flask/app.py", line 1477, in full_dispatch_request
    rv = self.handle_user_exception(e)
  File "/home/microblog/flask/local/lib/python2.7/site-packages/flask/app.py", line 1381, in handle_user_exception
    reraise(exc_type, exc_value, tb)
  File "/home/microblog/flask/local/lib/python2.7/site-packages/flask/app.py", line 1475, in full_dispatch_request
    rv = self.dispatch_request()
  File "/home/microblog/flask/local/lib/python2.7/site-packages/flask/app.py", line 1461, in dispatch_request
    return self.view_functions[rule.endpoint](**req.view_args)
  File "/home/microblog/flask/local/lib/python2.7/site-packages/flask_login.py", line 792, in decorated_view
    return func(*args, **kwargs)
  File "/home/microblog/app/views.py", line 73, in index
    posts = g.user.followed_posts().paginate(page, POSTS_PER_PAGE, False).items
NameError: global name 'page' is not defined
2015-11-04 14:34:12,368 ERROR: Exception on /index [GET] [in /home/microblog/flask/local/lib/python2.7/site-packages/flask/app.py:1423]
Traceback (most recent call last):
  File "/home/microblog/flask/local/lib/python2.7/site-packages/flask/app.py", line 1817, in wsgi_app
    response = self.full_dispatch_request()
  File "/home/microblog/flask/local/lib/python2.7/site-packages/flask/app.py", line 1477, in full_dispatch_request
    rv = self.handle_user_exception(e)
  File "/home/microblog/flask/local/lib/python2.7/site-packages/flask/app.py", line 1381, in handle_user_exception
    reraise(exc_type, exc_value, tb)
  File "/home/microblog/flask/local/lib/python2.7/site-packages/flask/app.py", line 1475, in full_dispatch_request
    rv = self.dispatch_request()
  File "/home/microblog/flask/local/lib/python2.7/site-packages/flask/app.py", line 1461, in dispatch_request
    return self.view_functions[rule.endpoint](**req.view_args)
  File "/home/microblog/flask/local/lib/python2.7/site-packages/flask_login.py", line 792, in decorated_view
    return func(*args, **kwargs)
  File "/home/microblog/app/views.py", line 73, in index
    posts = g.user.followed_posts().paginate(page, POSTS_PER_PAGE, False).items
NameError: global name 'page' is not defined
2015-11-04 14:34:15,079 ERROR: Exception on /index [GET] [in /home/microblog/flask/local/lib/python2.7/site-packages/flask/app.py:1423]
Traceback (most recent call last):
  File "/home/microblog/flask/local/lib/python2.7/site-packages/flask/app.py", line 1817, in wsgi_app
    response = self.full_dispatch_request()
  File "/home/microblog/flask/local/lib/python2.7/site-packages/flask/app.py", line 1477, in full_dispatch_request
    rv = self.handle_user_exception(e)
  File "/home/microblog/flask/local/lib/python2.7/site-packages/flask/app.py", line 1381, in handle_user_exception
    reraise(exc_type, exc_value, tb)
  File "/home/microblog/flask/local/lib/python2.7/site-packages/flask/app.py", line 1475, in full_dispatch_request
    rv = self.dispatch_request()
  File "/home/microblog/flask/local/lib/python2.7/site-packages/flask/app.py", line 1461, in dispatch_request
    return self.view_functions[rule.endpoint](**req.view_args)
  File "/home/microblog/flask/local/lib/python2.7/site-packages/flask_login.py", line 792, in decorated_view
    return func(*args, **kwargs)
  File "/home/microblog/app/views.py", line 73, in index
    posts = g.user.followed_posts().paginate(page, POSTS_PER_PAGE, False).items
NameError: global name 'page' is not defined
2015-11-04 14:34:16,709 ERROR: Exception on /index [GET] [in /home/microblog/flask/local/lib/python2.7/site-packages/flask/app.py:1423]
Traceback (most recent call last):
  File "/home/microblog/flask/local/lib/python2.7/site-packages/flask/app.py", line 1817, in wsgi_app
    response = self.full_dispatch_request()
  File "/home/microblog/flask/local/lib/python2.7/site-packages/flask/app.py", line 1477, in full_dispatch_request
    rv = self.handle_user_exception(e)
  File "/home/microblog/flask/local/lib/python2.7/site-packages/flask/app.py", line 1381, in handle_user_exception
    reraise(exc_type, exc_value, tb)
  File "/home/microblog/flask/local/lib/python2.7/site-packages/flask/app.py", line 1475, in full_dispatch_request
    rv = self.dispatch_request()
  File "/home/microblog/flask/local/lib/python2.7/site-packages/flask/app.py", line 1461, in dispatch_request
    return self.view_functions[rule.endpoint](**req.view_args)
  File "/home/microblog/flask/local/lib/python2.7/site-packages/flask_login.py", line 792, in decorated_view
    return func(*args, **kwargs)
  File "/home/microblog/app/views.py", line 73, in index
    posts = g.user.followed_posts().paginate(page, POSTS_PER_PAGE, False).items
NameError: global name 'page' is not defined
2015-11-04 14:34:18,208 ERROR: Exception on /index [GET] [in /home/microblog/flask/local/lib/python2.7/site-packages/flask/app.py:1423]
Traceback (most recent call last):
  File "/home/microblog/flask/local/lib/python2.7/site-packages/flask/app.py", line 1817, in wsgi_app
    response = self.full_dispatch_request()
  File "/home/microblog/flask/local/lib/python2.7/site-packages/flask/app.py", line 1477, in full_dispatch_request
    rv = self.handle_user_exception(e)
  File "/home/microblog/flask/local/lib/python2.7/site-packages/flask/app.py", line 1381, in handle_user_exception
    reraise(exc_type, exc_value, tb)
  File "/home/microblog/flask/local/lib/python2.7/site-packages/flask/app.py", line 1475, in full_dispatch_request
    rv = self.dispatch_request()
  File "/home/microblog/flask/local/lib/python2.7/site-packages/flask/app.py", line 1461, in dispatch_request
    return self.view_functions[rule.endpoint](**req.view_args)
  File "/home/microblog/flask/local/lib/python2.7/site-packages/flask_login.py", line 792, in decorated_view
    return func(*args, **kwargs)
  File "/home/microblog/app/views.py", line 73, in index
    posts = g.user.followed_posts().paginate(page, POSTS_PER_PAGE, False).items
NameError: global name 'page' is not defined
2015-11-04 14:34:27,104 ERROR: Exception on /index [GET] [in /home/microblog/flask/local/lib/python2.7/site-packages/flask/app.py:1423]
Traceback (most recent call last):
  File "/home/microblog/flask/local/lib/python2.7/site-packages/flask/app.py", line 1817, in wsgi_app
    response = self.full_dispatch_request()
  File "/home/microblog/flask/local/lib/python2.7/site-packages/flask/app.py", line 1477, in full_dispatch_request
    rv = self.handle_user_exception(e)
  File "/home/microblog/flask/local/lib/python2.7/site-packages/flask/app.py", line 1381, in handle_user_exception
    reraise(exc_type, exc_value, tb)
  File "/home/microblog/flask/local/lib/python2.7/site-packages/flask/app.py", line 1475, in full_dispatch_request
    rv = self.dispatch_request()
  File "/home/microblog/flask/local/lib/python2.7/site-packages/flask/app.py", line 1461, in dispatch_request
    return self.view_functions[rule.endpoint](**req.view_args)
  File "/home/microblog/flask/local/lib/python2.7/site-packages/flask_login.py", line 792, in decorated_view
    return func(*args, **kwargs)
  File "/home/microblog/app/views.py", line 73, in index
    posts = g.user.followed_posts().paginate(page, POSTS_PER_PAGE, False).items
NameError: global name 'page' is not defined
2015-11-04 14:34:45,885 ERROR: Exception on /index [GET] [in /home/microblog/flask/local/lib/python2.7/site-packages/flask/app.py:1423]
Traceback (most recent call last):
  File "/home/microblog/flask/local/lib/python2.7/site-packages/flask/app.py", line 1817, in wsgi_app
    response = self.full_dispatch_request()
  File "/home/microblog/flask/local/lib/python2.7/site-packages/flask/app.py", line 1477, in full_dispatch_request
    rv = self.handle_user_exception(e)
  File "/home/microblog/flask/local/lib/python2.7/site-packages/flask/app.py", line 1381, in handle_user_exception
    reraise(exc_type, exc_value, tb)
  File "/home/microblog/flask/local/lib/python2.7/site-packages/flask/app.py", line 1475, in full_dispatch_request
    rv = self.dispatch_request()
  File "/home/microblog/flask/local/lib/python2.7/site-packages/flask/app.py", line 1461, in dispatch_request
    return self.view_functions[rule.endpoint](**req.view_args)
  File "/home/microblog/flask/local/lib/python2.7/site-packages/flask_login.py", line 792, in decorated_view
    return func(*args, **kwargs)
  File "/home/microblog/app/views.py", line 73, in index
    posts = g.user.followed_posts().paginate(page, POSTS_PER_PAGE, False).items
NameError: global name 'page' is not defined
2015-11-04 14:34:50,228 ERROR: Exception on /index [GET] [in /home/microblog/flask/local/lib/python2.7/site-packages/flask/app.py:1423]
Traceback (most recent call last):
  File "/home/microblog/flask/local/lib/python2.7/site-packages/flask/app.py", line 1817, in wsgi_app
    response = self.full_dispatch_request()
  File "/home/microblog/flask/local/lib/python2.7/site-packages/flask/app.py", line 1477, in full_dispatch_request
    rv = self.handle_user_exception(e)
  File "/home/microblog/flask/local/lib/python2.7/site-packages/flask/app.py", line 1381, in handle_user_exception
    reraise(exc_type, exc_value, tb)
  File "/home/microblog/flask/local/lib/python2.7/site-packages/flask/app.py", line 1475, in full_dispatch_request
    rv = self.dispatch_request()
  File "/home/microblog/flask/local/lib/python2.7/site-packages/flask/app.py", line 1461, in dispatch_request
    return self.view_functions[rule.endpoint](**req.view_args)
  File "/home/microblog/flask/local/lib/python2.7/site-packages/flask_login.py", line 792, in decorated_view
    return func(*args, **kwargs)
  File "/home/microblog/app/views.py", line 73, in index
    posts = g.user.followed_posts().paginate(page, POSTS_PER_PAGE, False).items
NameError: global name 'page' is not defined
2015-11-04 14:34:50,721 ERROR: Exception on /index [GET] [in /home/microblog/flask/local/lib/python2.7/site-packages/flask/app.py:1423]
Traceback (most recent call last):
  File "/home/microblog/flask/local/lib/python2.7/site-packages/flask/app.py", line 1817, in wsgi_app
    response = self.full_dispatch_request()
  File "/home/microblog/flask/local/lib/python2.7/site-packages/flask/app.py", line 1477, in full_dispatch_request
    rv = self.handle_user_exception(e)
  File "/home/microblog/flask/local/lib/python2.7/site-packages/flask/app.py", line 1381, in handle_user_exception
    reraise(exc_type, exc_value, tb)
  File "/home/microblog/flask/local/lib/python2.7/site-packages/flask/app.py", line 1475, in full_dispatch_request
    rv = self.dispatch_request()
  File "/home/microblog/flask/local/lib/python2.7/site-packages/flask/app.py", line 1461, in dispatch_request
    return self.view_functions[rule.endpoint](**req.view_args)
  File "/home/microblog/flask/local/lib/python2.7/site-packages/flask_login.py", line 792, in decorated_view
    return func(*args, **kwargs)
  File "/home/microblog/app/views.py", line 73, in index
    posts = g.user.followed_posts().paginate(page, POSTS_PER_PAGE, False).items
NameError: global name 'page' is not defined
2015-11-04 14:35:12,645 ERROR: Exception on /index [GET] [in /home/microblog/flask/local/lib/python2.7/site-packages/flask/app.py:1423]
Traceback (most recent call last):
  File "/home/microblog/flask/local/lib/python2.7/site-packages/flask/app.py", line 1817, in wsgi_app
    response = self.full_dispatch_request()
  File "/home/microblog/flask/local/lib/python2.7/site-packages/flask/app.py", line 1477, in full_dispatch_request
    rv = self.handle_user_exception(e)
  File "/home/microblog/flask/local/lib/python2.7/site-packages/flask/app.py", line 1381, in handle_user_exception
    reraise(exc_type, exc_value, tb)
  File "/home/microblog/flask/local/lib/python2.7/site-packages/flask/app.py", line 1475, in full_dispatch_request
    rv = self.dispatch_request()
  File "/home/microblog/flask/local/lib/python2.7/site-packages/flask/app.py", line 1461, in dispatch_request
    return self.view_functions[rule.endpoint](**req.view_args)
  File "/home/microblog/flask/local/lib/python2.7/site-packages/flask_login.py", line 792, in decorated_view
    return func(*args, **kwargs)
  File "/home/microblog/app/views.py", line 73, in index
    posts = g.user.followed_posts().paginate(page, POSTS_PER_PAGE, False).items
NameError: global name 'page' is not defined
2015-11-04 14:35:26,787 ERROR: Exception on /index [GET] [in /home/microblog/flask/local/lib/python2.7/site-packages/flask/app.py:1423]
Traceback (most recent call last):
  File "/home/microblog/flask/local/lib/python2.7/site-packages/flask/app.py", line 1817, in wsgi_app
    response = self.full_dispatch_request()
  File "/home/microblog/flask/local/lib/python2.7/site-packages/flask/app.py", line 1477, in full_dispatch_request
    rv = self.handle_user_exception(e)
  File "/home/microblog/flask/local/lib/python2.7/site-packages/flask/app.py", line 1381, in handle_user_exception
    reraise(exc_type, exc_value, tb)
  File "/home/microblog/flask/local/lib/python2.7/site-packages/flask/app.py", line 1475, in full_dispatch_request
    rv = self.dispatch_request()
  File "/home/microblog/flask/local/lib/python2.7/site-packages/flask/app.py", line 1461, in dispatch_request
    return self.view_functions[rule.endpoint](**req.view_args)
  File "/home/microblog/flask/local/lib/python2.7/site-packages/flask_login.py", line 792, in decorated_view
    return func(*args, **kwargs)
  File "/home/microblog/app/views.py", line 73, in index
    posts = g.user.followed_posts().paginate(page, POSTS_PER_PAGE, False).items
NameError: global name 'page' is not defined
2015-11-04 14:35:33,877 ERROR: Exception on /index [GET] [in /home/microblog/flask/local/lib/python2.7/site-packages/flask/app.py:1423]
Traceback (most recent call last):
  File "/home/microblog/flask/local/lib/python2.7/site-packages/flask/app.py", line 1817, in wsgi_app
    response = self.full_dispatch_request()
  File "/home/microblog/flask/local/lib/python2.7/site-packages/flask/app.py", line 1477, in full_dispatch_request
    rv = self.handle_user_exception(e)
  File "/home/microblog/flask/local/lib/python2.7/site-packages/flask/app.py", line 1381, in handle_user_exception
    reraise(exc_type, exc_value, tb)
  File "/home/microblog/flask/local/lib/python2.7/site-packages/flask/app.py", line 1475, in full_dispatch_request
    rv = self.dispatch_request()
  File "/home/microblog/flask/local/lib/python2.7/site-packages/flask/app.py", line 1461, in dispatch_request
    return self.view_functions[rule.endpoint](**req.view_args)
  File "/home/microblog/flask/local/lib/python2.7/site-packages/flask_login.py", line 792, in decorated_view
    return func(*args, **kwargs)
  File "/home/microblog/app/views.py", line 73, in index
    posts = g.user.followed_posts().paginate(page, POSTS_PER_PAGE, False).items
NameError: global name 'page' is not defined
2015-11-04 14:37:45,209 INFO: microblog startup [in /home/microblog/app/__init__.py:36]
2015-11-04 14:38:16,082 INFO: microblog startup [in /home/microblog/app/__init__.py:36]
2015-11-04 14:38:49,450 INFO: microblog startup [in /home/microblog/app/__init__.py:36]
2015-11-04 14:38:53,444 ERROR: Exception on /index [GET] [in /home/microblog/flask/local/lib/python2.7/site-packages/flask/app.py:1423]
Traceback (most recent call last):
  File "/home/microblog/flask/local/lib/python2.7/site-packages/flask/app.py", line 1817, in wsgi_app
    response = self.full_dispatch_request()
  File "/home/microblog/flask/local/lib/python2.7/site-packages/flask/app.py", line 1477, in full_dispatch_request
    rv = self.handle_user_exception(e)
  File "/home/microblog/flask/local/lib/python2.7/site-packages/flask/app.py", line 1381, in handle_user_exception
    reraise(exc_type, exc_value, tb)
  File "/home/microblog/flask/local/lib/python2.7/site-packages/flask/app.py", line 1475, in full_dispatch_request
    rv = self.dispatch_request()
  File "/home/microblog/flask/local/lib/python2.7/site-packages/flask/app.py", line 1461, in dispatch_request
    return self.view_functions[rule.endpoint](**req.view_args)
  File "/home/microblog/flask/local/lib/python2.7/site-packages/flask_login.py", line 792, in decorated_view
    return func(*args, **kwargs)
  File "/home/microblog/app/views.py", line 73, in index
    posts = g.user.followed_posts().paginate(page, POSTS_PER_PAGE, False).items
NameError: global name 'page' is not defined
2015-11-04 14:42:35,910 INFO: microblog startup [in /home/microblog/app/__init__.py:36]
2015-11-04 14:43:24,548 ERROR: Exception on /index/2 [GET] [in /home/microblog/flask/local/lib/python2.7/site-packages/flask/app.py:1423]
Traceback (most recent call last):
  File "/home/microblog/flask/local/lib/python2.7/site-packages/flask/app.py", line 1817, in wsgi_app
    response = self.full_dispatch_request()
  File "/home/microblog/flask/local/lib/python2.7/site-packages/flask/app.py", line 1477, in full_dispatch_request
    rv = self.handle_user_exception(e)
  File "/home/microblog/flask/local/lib/python2.7/site-packages/flask/app.py", line 1381, in handle_user_exception
    reraise(exc_type, exc_value, tb)
  File "/home/microblog/flask/local/lib/python2.7/site-packages/flask/app.py", line 1475, in full_dispatch_request
    rv = self.dispatch_request()
  File "/home/microblog/flask/local/lib/python2.7/site-packages/flask/app.py", line 1461, in dispatch_request
    return self.view_functions[rule.endpoint](**req.view_args)
  File "/home/microblog/flask/local/lib/python2.7/site-packages/flask_login.py", line 792, in decorated_view
    return func(*args, **kwargs)
TypeError: index() takes no arguments (1 given)
2015-11-04 14:43:37,693 ERROR: Exception on /index/1 [GET] [in /home/microblog/flask/local/lib/python2.7/site-packages/flask/app.py:1423]
Traceback (most recent call last):
  File "/home/microblog/flask/local/lib/python2.7/site-packages/flask/app.py", line 1817, in wsgi_app
    response = self.full_dispatch_request()
  File "/home/microblog/flask/local/lib/python2.7/site-packages/flask/app.py", line 1477, in full_dispatch_request
    rv = self.handle_user_exception(e)
  File "/home/microblog/flask/local/lib/python2.7/site-packages/flask/app.py", line 1381, in handle_user_exception
    reraise(exc_type, exc_value, tb)
  File "/home/microblog/flask/local/lib/python2.7/site-packages/flask/app.py", line 1475, in full_dispatch_request
    rv = self.dispatch_request()
  File "/home/microblog/flask/local/lib/python2.7/site-packages/flask/app.py", line 1461, in dispatch_request
    return self.view_functions[rule.endpoint](**req.view_args)
  File "/home/microblog/flask/local/lib/python2.7/site-packages/flask_login.py", line 792, in decorated_view
    return func(*args, **kwargs)
TypeError: index() takes no arguments (1 given)
2015-11-04 14:44:31,194 ERROR: Exception on /index/2 [GET] [in /home/microblog/flask/local/lib/python2.7/site-packages/flask/app.py:1423]
Traceback (most recent call last):
  File "/home/microblog/flask/local/lib/python2.7/site-packages/flask/app.py", line 1817, in wsgi_app
    response = self.full_dispatch_request()
  File "/home/microblog/flask/local/lib/python2.7/site-packages/flask/app.py", line 1477, in full_dispatch_request
    rv = self.handle_user_exception(e)
  File "/home/microblog/flask/local/lib/python2.7/site-packages/flask/app.py", line 1381, in handle_user_exception
    reraise(exc_type, exc_value, tb)
  File "/home/microblog/flask/local/lib/python2.7/site-packages/flask/app.py", line 1475, in full_dispatch_request
    rv = self.dispatch_request()
  File "/home/microblog/flask/local/lib/python2.7/site-packages/flask/app.py", line 1461, in dispatch_request
    return self.view_functions[rule.endpoint](**req.view_args)
  File "/home/microblog/flask/local/lib/python2.7/site-packages/flask_login.py", line 792, in decorated_view
    return func(*args, **kwargs)
TypeError: index() takes no arguments (1 given)
2015-11-04 14:45:29,691 INFO: microblog startup [in /home/microblog/app/__init__.py:36]
2015-11-04 14:45:39,728 ERROR: Exception on /index/2 [GET] [in /home/microblog/flask/local/lib/python2.7/site-packages/flask/app.py:1423]
Traceback (most recent call last):
  File "/home/microblog/flask/local/lib/python2.7/site-packages/flask/app.py", line 1817, in wsgi_app
    response = self.full_dispatch_request()
  File "/home/microblog/flask/local/lib/python2.7/site-packages/flask/app.py", line 1477, in full_dispatch_request
    rv = self.handle_user_exception(e)
  File "/home/microblog/flask/local/lib/python2.7/site-packages/flask/app.py", line 1381, in handle_user_exception
    reraise(exc_type, exc_value, tb)
  File "/home/microblog/flask/local/lib/python2.7/site-packages/flask/app.py", line 1475, in full_dispatch_request
    rv = self.dispatch_request()
  File "/home/microblog/flask/local/lib/python2.7/site-packages/flask/app.py", line 1461, in dispatch_request
    return self.view_functions[rule.endpoint](**req.view_args)
  File "/home/microblog/flask/local/lib/python2.7/site-packages/flask_login.py", line 792, in decorated_view
    return func(*args, **kwargs)
TypeError: index() takes no arguments (1 given)
2015-11-04 14:45:44,023 ERROR: Exception on /index/1 [GET] [in /home/microblog/flask/local/lib/python2.7/site-packages/flask/app.py:1423]
Traceback (most recent call last):
  File "/home/microblog/flask/local/lib/python2.7/site-packages/flask/app.py", line 1817, in wsgi_app
    response = self.full_dispatch_request()
  File "/home/microblog/flask/local/lib/python2.7/site-packages/flask/app.py", line 1477, in full_dispatch_request
    rv = self.handle_user_exception(e)
  File "/home/microblog/flask/local/lib/python2.7/site-packages/flask/app.py", line 1381, in handle_user_exception
    reraise(exc_type, exc_value, tb)
  File "/home/microblog/flask/local/lib/python2.7/site-packages/flask/app.py", line 1475, in full_dispatch_request
    rv = self.dispatch_request()
  File "/home/microblog/flask/local/lib/python2.7/site-packages/flask/app.py", line 1461, in dispatch_request
    return self.view_functions[rule.endpoint](**req.view_args)
  File "/home/microblog/flask/local/lib/python2.7/site-packages/flask_login.py", line 792, in decorated_view
    return func(*args, **kwargs)
TypeError: index() takes no arguments (1 given)
2015-11-04 14:46:37,271 INFO: microblog startup [in /home/microblog/app/__init__.py:36]
2015-11-04 14:46:40,580 ERROR: Exception on /index [GET] [in /home/microblog/flask/local/lib/python2.7/site-packages/flask/app.py:1423]
Traceback (most recent call last):
  File "/home/microblog/flask/local/lib/python2.7/site-packages/flask/app.py", line 1817, in wsgi_app
    response = self.full_dispatch_request()
  File "/home/microblog/flask/local/lib/python2.7/site-packages/flask/app.py", line 1477, in full_dispatch_request
    rv = self.handle_user_exception(e)
  File "/home/microblog/flask/local/lib/python2.7/site-packages/flask/app.py", line 1381, in handle_user_exception
    reraise(exc_type, exc_value, tb)
  File "/home/microblog/flask/local/lib/python2.7/site-packages/flask/app.py", line 1475, in full_dispatch_request
    rv = self.dispatch_request()
  File "/home/microblog/flask/local/lib/python2.7/site-packages/flask/app.py", line 1461, in dispatch_request
    return self.view_functions[rule.endpoint](**req.view_args)
  File "/home/microblog/flask/local/lib/python2.7/site-packages/flask_login.py", line 792, in decorated_view
    return func(*args, **kwargs)
  File "/home/microblog/app/views.py", line 73, in index
    posts = g.user.followed_posts().paginate(page, POSTS_PER_PAGE, False).items
NameError: global name 'page' is not defined
2015-11-04 14:48:20,684 INFO: microblog startup [in /home/microblog/app/__init__.py:36]
2015-11-04 15:29:47,780 INFO: microblog startup [in /home/microblog/app/__init__.py:36]
2015-11-04 15:35:19,058 INFO: microblog startup [in /home/microblog/app/__init__.py:36]
2015-11-04 16:05:33,226 INFO: microblog startup [in /home/microblog/app/__init__.py:36]
2015-11-04 16:09:17,855 INFO: microblog startup [in /home/microblog/app/__init__.py:36]
2015-11-04 16:11:17,581 INFO: microblog startup [in /home/microblog/app/__init__.py:36]
2015-11-04 16:11:20,852 ERROR: Exception on /user/Mara Gatchalian [GET] [in /home/microblog/flask/local/lib/python2.7/site-packages/flask/app.py:1423]
Traceback (most recent call last):
  File "/home/microblog/flask/local/lib/python2.7/site-packages/flask/app.py", line 1817, in wsgi_app
    response = self.full_dispatch_request()
  File "/home/microblog/flask/local/lib/python2.7/site-packages/flask/app.py", line 1477, in full_dispatch_request
    rv = self.handle_user_exception(e)
  File "/home/microblog/flask/local/lib/python2.7/site-packages/flask/app.py", line 1381, in handle_user_exception
    reraise(exc_type, exc_value, tb)
  File "/home/microblog/flask/local/lib/python2.7/site-packages/flask/app.py", line 1475, in full_dispatch_request
    rv = self.dispatch_request()
  File "/home/microblog/flask/local/lib/python2.7/site-packages/flask/app.py", line 1461, in dispatch_request
    return self.view_functions[rule.endpoint](**req.view_args)
  File "/home/microblog/flask/local/lib/python2.7/site-packages/flask_login.py", line 792, in decorated_view
    return func(*args, **kwargs)
  File "/home/microblog/app/views.py", line 106, in user
    posts=posts)
UnboundLocalError: local variable 'posts' referenced before assignment
2015-11-04 16:12:50,468 INFO: microblog startup [in /home/microblog/app/__init__.py:36]
2015-11-04 16:13:05,591 INFO: microblog startup [in /home/microblog/app/__init__.py:36]
2015-11-04 16:14:31,956 INFO: microblog startup [in /home/microblog/app/__init__.py:36]
2015-11-04 16:16:17,401 INFO: microblog startup [in /home/microblog/app/__init__.py:36]
2015-11-04 16:16:20,466 ERROR: Exception on /user/Mara Gatchalian [GET] [in /home/microblog/flask/local/lib/python2.7/site-packages/flask/app.py:1423]
Traceback (most recent call last):
  File "/home/microblog/flask/local/lib/python2.7/site-packages/flask/app.py", line 1817, in wsgi_app
    response = self.full_dispatch_request()
  File "/home/microblog/flask/local/lib/python2.7/site-packages/flask/app.py", line 1477, in full_dispatch_request
    rv = self.handle_user_exception(e)
  File "/home/microblog/flask/local/lib/python2.7/site-packages/flask/app.py", line 1381, in handle_user_exception
    reraise(exc_type, exc_value, tb)
  File "/home/microblog/flask/local/lib/python2.7/site-packages/flask/app.py", line 1475, in full_dispatch_request
    rv = self.dispatch_request()
  File "/home/microblog/flask/local/lib/python2.7/site-packages/flask/app.py", line 1461, in dispatch_request
    return self.view_functions[rule.endpoint](**req.view_args)
  File "/home/microblog/flask/local/lib/python2.7/site-packages/flask_login.py", line 792, in decorated_view
    return func(*args, **kwargs)
  File "/home/microblog/app/views.py", line 102, in user
    posts=posts)
UnboundLocalError: local variable 'posts' referenced before assignment
2015-11-04 16:16:47,299 INFO: microblog startup [in /home/microblog/app/__init__.py:36]
2015-11-04 16:18:56,322 INFO: microblog startup [in /home/microblog/app/__init__.py:36]
2015-11-04 16:19:00,078 ERROR: Exception on /user/Mara Gatchalian [GET] [in /home/microblog/flask/local/lib/python2.7/site-packages/flask/app.py:1423]
Traceback (most recent call last):
  File "/home/microblog/flask/local/lib/python2.7/site-packages/flask/app.py", line 1817, in wsgi_app
    response = self.full_dispatch_request()
  File "/home/microblog/flask/local/lib/python2.7/site-packages/flask/app.py", line 1477, in full_dispatch_request
    rv = self.handle_user_exception(e)
  File "/home/microblog/flask/local/lib/python2.7/site-packages/flask/app.py", line 1381, in handle_user_exception
    reraise(exc_type, exc_value, tb)
  File "/home/microblog/flask/local/lib/python2.7/site-packages/flask/app.py", line 1475, in full_dispatch_request
    rv = self.dispatch_request()
  File "/home/microblog/flask/local/lib/python2.7/site-packages/flask/app.py", line 1461, in dispatch_request
    return self.view_functions[rule.endpoint](**req.view_args)
  File "/home/microblog/flask/local/lib/python2.7/site-packages/flask_login.py", line 792, in decorated_view
    return func(*args, **kwargs)
  File "/home/microblog/app/views.py", line 101, in user
    posts=posts)
UnboundLocalError: local variable 'posts' referenced before assignment
2015-11-04 16:19:09,546 ERROR: Exception on /user/Mara Gatchalian [GET] [in /home/microblog/flask/local/lib/python2.7/site-packages/flask/app.py:1423]
Traceback (most recent call last):
  File "/home/microblog/flask/local/lib/python2.7/site-packages/flask/app.py", line 1817, in wsgi_app
    response = self.full_dispatch_request()
  File "/home/microblog/flask/local/lib/python2.7/site-packages/flask/app.py", line 1477, in full_dispatch_request
    rv = self.handle_user_exception(e)
  File "/home/microblog/flask/local/lib/python2.7/site-packages/flask/app.py", line 1381, in handle_user_exception
    reraise(exc_type, exc_value, tb)
  File "/home/microblog/flask/local/lib/python2.7/site-packages/flask/app.py", line 1475, in full_dispatch_request
    rv = self.dispatch_request()
  File "/home/microblog/flask/local/lib/python2.7/site-packages/flask/app.py", line 1461, in dispatch_request
    return self.view_functions[rule.endpoint](**req.view_args)
  File "/home/microblog/flask/local/lib/python2.7/site-packages/flask_login.py", line 792, in decorated_view
    return func(*args, **kwargs)
  File "/home/microblog/app/views.py", line 101, in user
    posts=posts)
UnboundLocalError: local variable 'posts' referenced before assignment
2015-11-04 16:20:02,962 INFO: microblog startup [in /home/microblog/app/__init__.py:36]
2015-11-04 16:20:13,456 ERROR: Exception on /user/Mara Gatchalian [GET] [in /home/microblog/flask/local/lib/python2.7/site-packages/flask/app.py:1423]
Traceback (most recent call last):
  File "/home/microblog/flask/local/lib/python2.7/site-packages/flask/app.py", line 1817, in wsgi_app
    response = self.full_dispatch_request()
  File "/home/microblog/flask/local/lib/python2.7/site-packages/flask/app.py", line 1477, in full_dispatch_request
    rv = self.handle_user_exception(e)
  File "/home/microblog/flask/local/lib/python2.7/site-packages/flask/app.py", line 1381, in handle_user_exception
    reraise(exc_type, exc_value, tb)
  File "/home/microblog/flask/local/lib/python2.7/site-packages/flask/app.py", line 1475, in full_dispatch_request
    rv = self.dispatch_request()
  File "/home/microblog/flask/local/lib/python2.7/site-packages/flask/app.py", line 1461, in dispatch_request
    return self.view_functions[rule.endpoint](**req.view_args)
  File "/home/microblog/flask/local/lib/python2.7/site-packages/flask_login.py", line 792, in decorated_view
    return func(*args, **kwargs)
  File "/home/microblog/app/views.py", line 101, in user
    posts=posts)
  File "/home/microblog/flask/local/lib/python2.7/site-packages/flask/templating.py", line 128, in render_template
    context, ctx.app)
  File "/home/microblog/flask/local/lib/python2.7/site-packages/flask/templating.py", line 110, in _render
    rv = template.render(context)
  File "/home/microblog/flask/local/lib/python2.7/site-packages/jinja2/environment.py", line 989, in render
    return self.environment.handle_exception(exc_info, True)
  File "/home/microblog/flask/local/lib/python2.7/site-packages/jinja2/environment.py", line 754, in handle_exception
    reraise(exc_type, exc_value, tb)
  File "/home/microblog/app/templates/user.html", line 2, in top-level template code
    {% extends "base.html" %}
  File "/home/microblog/app/templates/base.html", line 33, in top-level template code
    {% block content %}{% endblock %}
  File "/home/microblog/app/templates/user.html", line 26, in block "content"
    {% for post in posts %}
TypeError: 'Pagination' object is not iterable
2015-11-04 16:20:15,763 ERROR: Exception on /user/Mara Gatchalian [GET] [in /home/microblog/flask/local/lib/python2.7/site-packages/flask/app.py:1423]
Traceback (most recent call last):
  File "/home/microblog/flask/local/lib/python2.7/site-packages/flask/app.py", line 1817, in wsgi_app
    response = self.full_dispatch_request()
  File "/home/microblog/flask/local/lib/python2.7/site-packages/flask/app.py", line 1477, in full_dispatch_request
    rv = self.handle_user_exception(e)
  File "/home/microblog/flask/local/lib/python2.7/site-packages/flask/app.py", line 1381, in handle_user_exception
    reraise(exc_type, exc_value, tb)
  File "/home/microblog/flask/local/lib/python2.7/site-packages/flask/app.py", line 1475, in full_dispatch_request
    rv = self.dispatch_request()
  File "/home/microblog/flask/local/lib/python2.7/site-packages/flask/app.py", line 1461, in dispatch_request
    return self.view_functions[rule.endpoint](**req.view_args)
  File "/home/microblog/flask/local/lib/python2.7/site-packages/flask_login.py", line 792, in decorated_view
    return func(*args, **kwargs)
  File "/home/microblog/app/views.py", line 101, in user
    posts=posts)
  File "/home/microblog/flask/local/lib/python2.7/site-packages/flask/templating.py", line 128, in render_template
    context, ctx.app)
  File "/home/microblog/flask/local/lib/python2.7/site-packages/flask/templating.py", line 110, in _render
    rv = template.render(context)
  File "/home/microblog/flask/local/lib/python2.7/site-packages/jinja2/environment.py", line 989, in render
    return self.environment.handle_exception(exc_info, True)
  File "/home/microblog/flask/local/lib/python2.7/site-packages/jinja2/environment.py", line 754, in handle_exception
    reraise(exc_type, exc_value, tb)
  File "/home/microblog/app/templates/user.html", line 2, in top-level template code
    {% extends "base.html" %}
  File "/home/microblog/app/templates/base.html", line 33, in top-level template code
    {% block content %}{% endblock %}
  File "/home/microblog/app/templates/user.html", line 26, in block "content"
    {% for post in posts %}
TypeError: 'Pagination' object is not iterable
2015-11-04 16:20:30,094 ERROR: Exception on /user/Mara Gatchalian [GET] [in /home/microblog/flask/local/lib/python2.7/site-packages/flask/app.py:1423]
Traceback (most recent call last):
  File "/home/microblog/flask/local/lib/python2.7/site-packages/flask/app.py", line 1817, in wsgi_app
    response = self.full_dispatch_request()
  File "/home/microblog/flask/local/lib/python2.7/site-packages/flask/app.py", line 1477, in full_dispatch_request
    rv = self.handle_user_exception(e)
  File "/home/microblog/flask/local/lib/python2.7/site-packages/flask/app.py", line 1381, in handle_user_exception
    reraise(exc_type, exc_value, tb)
  File "/home/microblog/flask/local/lib/python2.7/site-packages/flask/app.py", line 1475, in full_dispatch_request
    rv = self.dispatch_request()
  File "/home/microblog/flask/local/lib/python2.7/site-packages/flask/app.py", line 1461, in dispatch_request
    return self.view_functions[rule.endpoint](**req.view_args)
  File "/home/microblog/flask/local/lib/python2.7/site-packages/flask_login.py", line 792, in decorated_view
    return func(*args, **kwargs)
  File "/home/microblog/app/views.py", line 101, in user
    posts=posts)
  File "/home/microblog/flask/local/lib/python2.7/site-packages/flask/templating.py", line 128, in render_template
    context, ctx.app)
  File "/home/microblog/flask/local/lib/python2.7/site-packages/flask/templating.py", line 110, in _render
    rv = template.render(context)
  File "/home/microblog/flask/local/lib/python2.7/site-packages/jinja2/environment.py", line 989, in render
    return self.environment.handle_exception(exc_info, True)
  File "/home/microblog/flask/local/lib/python2.7/site-packages/jinja2/environment.py", line 754, in handle_exception
    reraise(exc_type, exc_value, tb)
  File "/home/microblog/app/templates/user.html", line 2, in top-level template code
    {% extends "base.html" %}
  File "/home/microblog/app/templates/base.html", line 33, in top-level template code
    {% block content %}{% endblock %}
  File "/home/microblog/app/templates/user.html", line 26, in block "content"
    {% for post in posts %}
TypeError: 'Pagination' object is not iterable
2015-11-04 16:22:06,453 INFO: microblog startup [in /home/microblog/app/__init__.py:36]
2015-11-05 10:09:11,318 INFO: microblog startup [in app/__init__.py:36]
2015-11-05 10:09:20,670 INFO: microblog startup [in app/__init__.py:36]
2015-11-05 10:09:50,454 INFO: microblog startup [in app/__init__.py:36]
2015-11-05 10:10:40,159 INFO: microblog startup [in app/__init__.py:36]
2015-11-05 10:14:14,538 INFO: microblog startup [in app/__init__.py:36]
2015-11-05 10:19:58,789 INFO: microblog startup [in /home/microblog/app/__init__.py:36]
2015-11-05 10:42:52,622 INFO: microblog startup [in /home/microblog/app/__init__.py:36]
2015-11-05 10:46:30,846 INFO: microblog startup [in /home/microblog/app/__init__.py:36]
2015-11-05 10:51:41,085 INFO: microblog startup [in /home/microblog/app/__init__.py:36]
2015-11-05 10:59:22,614 INFO: microblog startup [in /home/microblog/app/__init__.py:36]
2015-11-05 11:13:18,774 INFO: microblog startup [in app/__init__.py:39]
2015-11-05 11:42:56,067 INFO: microblog startup [in app/__init__.py:39]
2015-11-05 11:51:48,694 INFO: microblog startup [in app/__init__.py:39]
2015-11-05 12:01:12,502 INFO: microblog startup [in app/__init__.py:39]
2015-11-05 12:09:03,730 INFO: microblog startup [in app/__init__.py:40]
2015-11-05 12:11:39,144 INFO: microblog startup [in app/__init__.py:38]
2015-11-05 12:31:24,921 INFO: microblog startup [in /home/microblog/app/__init__.py:38]
2015-11-05 12:31:26,410 INFO: microblog startup [in /home/microblog/app/__init__.py:38]
2015-11-05 12:31:31,206 INFO: microblog startup [in /home/microblog/app/__init__.py:38]
2015-11-05 13:34:27,838 INFO: microblog startup [in /home/microblog/app/__init__.py:38]
2015-11-05 13:41:46,029 INFO: microblog startup [in app/__init__.py:38]
2015-11-05 13:43:34,751 INFO: microblog startup [in app/__init__.py:38]
2015-11-05 13:54:35,723 INFO: microblog startup [in /home/microblog/app/__init__.py:38]
2015-11-05 13:58:32,221 INFO: microblog startup [in /home/microblog/app/__init__.py:38]
2015-11-05 13:59:55,588 INFO: microblog startup [in app/__init__.py:38]
2015-11-05 14:07:47,880 INFO: microblog startup [in /home/microblog/app/__init__.py:38]
2015-11-05 14:17:08,529 INFO: microblog startup [in app/__init__.py:38]
2015-11-05 14:22:03,567 INFO: microblog startup [in app/__init__.py:38]
2015-11-05 14:24:56,835 INFO: microblog startup [in app/__init__.py:38]
2015-11-05 14:28:04,887 INFO: microblog startup [in app/__init__.py:38]
2015-11-05 14:40:45,092 INFO: microblog startup [in app/__init__.py:38]
2015-11-05 14:43:40,521 INFO: microblog startup [in /home/microblog/app/__init__.py:38]
2015-11-05 14:55:08,348 INFO: microblog startup [in app/__init__.py:38]
2015-11-05 15:17:50,953 INFO: microblog startup [in app/__init__.py:38]
2015-11-05 15:31:31,324 INFO: microblog startup [in app/__init__.py:38]
2015-11-05 15:38:56,291 INFO: microblog startup [in app/__init__.py:38]
2015-11-05 16:02:02,890 INFO: microblog startup [in /home/microblog/app/__init__.py:38]
